Workbook

Sheet Summary
A1: Legal Lens — end-to-end functional test report
A2: Playwright against the live UI (localhost:5173) and the live backend (127.0.0.1:8000), LL_AI_ENGINE=auto resolving to orchestrated/m4 — real bge-m3 retrieval, real Claude Sonnet 5 generation.
A4: Executed | B4: 2026-10-13 / 2026-10-14 (local)
A5: Build under test | B5: branch feature/webcode, commit 9ee3e46 (+ one fix applied during the run — see TC-60)
A6: Frontend | B6: React 19 · Vite dev server · http://localhost:5173
A7: Backend | B7: FastAPI · uvicorn · http://127.0.0.1:8000
A8: Generation engine | B8: orchestrated/m4 · claude-sonnet-5 · prompt ask/v1.0.0+f95069f0
A9: Intent router | B9: claude-haiku-4-5 · temperature 0.0
A10: Retrieval | B10: BAAI/bge-m3 dense+sparse → Qdrant (local, data/qdrant) → RRF → BAAI/bge-reranker-v2-m3, CPU
A11: Grounded | B11: true (GET /readyz → generation.grounded = true) — no fixture answers in this run
A12: Test method | B12: Functional, black-box through the browser; every UI assertion cross-checked against the REST API
A13: Documents used | B13: 3 uploaded through the real ingestion pipeline + 9 pre-seeded fixture documents
A15: RESULTS
B16: Live formula | C16: Verified at run time
A17: Total test cases | B17: =COUNTA('Test Cases'!A4:A1000) -> 60 | C17: 60
A18: Passed | B18: =COUNTIF('Test Cases'!F4:F1000,"PASS") -> 54 | C18: 54
A19: Failed | B19: =COUNTIF('Test Cases'!F4:F1000,"FAIL") -> 6 | C19: 6
A20: Pass rate | B20: =IFERROR(B18/B17,0) -> 0.9 | C20: 0.9
A21: Column B recalculates from the Test Cases sheet when opened in Excel. Column C is the count observed by the harness at run time, recorded so the figures are readable without recalculation; the two agreed when this file was written.
A23: BY SCENARIO
A24: Scenario | B24: Cases | C24: Passed | D24: Failed | E24: Verified cases | F24: Verified failed
A25: Authentication | B25: =COUNTIF('Test Cases'!B4:B1000,A25) -> 5 | C25: =COUNTIFS('Test Cases'!B4:B1000,A25,'Test Cases'!F4:F1000,"PASS") -> 5 | D25: =COUNTIFS('Test Cases'!B4:B1000,A25,'Test Cases'!F4:F1000,"FAIL") -> 0 | E25: 5 | F25: 0
A26: Composer controls | B26: =COUNTIF('Test Cases'!B4:B1000,A26) -> 4 | C26: =COUNTIFS('Test Cases'!B4:B1000,A26,'Test Cases'!F4:F1000,"PASS") -> 4 | D26: =COUNTIFS('Test Cases'!B4:B1000,A26,'Test Cases'!F4:F1000,"FAIL") -> 0 | E26: 4 | F26: 0
A27: Conversation management | B27: =COUNTIF('Test Cases'!B4:B1000,A27) -> 1 | C27: =COUNTIFS('Test Cases'!B4:B1000,A27,'Test Cases'!F4:F1000,"PASS") -> 1 | D27: =COUNTIFS('Test Cases'!B4:B1000,A27,'Test Cases'!F4:F1000,"FAIL") -> 0 | E27: 1 | F27: 0
A28: Document library | B28: =COUNTIF('Test Cases'!B4:B1000,A28) -> 2 | C28: =COUNTIFS('Test Cases'!B4:B1000,A28,'Test Cases'!F4:F1000,"PASS") -> 2 | D28: =COUNTIFS('Test Cases'!B4:B1000,A28,'Test Cases'!F4:F1000,"FAIL") -> 0 | E28: 2 | F28: 0
A29: Guardrails | B29: =COUNTIF('Test Cases'!B4:B1000,A29) -> 2 | C29: =COUNTIFS('Test Cases'!B4:B1000,A29,'Test Cases'!F4:F1000,"PASS") -> 1 | D29: =COUNTIFS('Test Cases'!B4:B1000,A29,'Test Cases'!F4:F1000,"FAIL") -> 1 | E29: 2 | F29: 1
A30: Interactive shell | B30: =COUNTIF('Test Cases'!B4:B1000,A30) -> 3 | C30: =COUNTIFS('Test Cases'!B4:B1000,A30,'Test Cases'!F4:F1000,"PASS") -> 3 | D30: =COUNTIFS('Test Cases'!B4:B1000,A30,'Test Cases'!F4:F1000,"FAIL") -> 0 | E30: 3 | F30: 0
A31: Navigation | B31: =COUNTIF('Test Cases'!B4:B1000,A31) -> 3 | C31: =COUNTIFS('Test Cases'!B4:B1000,A31,'Test Cases'!F4:F1000,"PASS") -> 3 | D31: =COUNTIFS('Test Cases'!B4:B1000,A31,'Test Cases'!F4:F1000,"FAIL") -> 0 | E31: 3 | F31: 0
A32: Output handling | B32: =COUNTIF('Test Cases'!B4:B1000,A32) -> 2 | C32: =COUNTIFS('Test Cases'!B4:B1000,A32,'Test Cases'!F4:F1000,"PASS") -> 2 | D32: =COUNTIFS('Test Cases'!B4:B1000,A32,'Test Cases'!F4:F1000,"FAIL") -> 0 | E32: 2 | F32: 0
A33: Performance | B33: =COUNTIF('Test Cases'!B4:B1000,A33) -> 1 | C33: =COUNTIFS('Test Cases'!B4:B1000,A33,'Test Cases'!F4:F1000,"PASS") -> 0 | D33: =COUNTIFS('Test Cases'!B4:B1000,A33,'Test Cases'!F4:F1000,"FAIL") -> 1 | E33: 1 | F33: 1
A34: S1 · Ask workflow | B34: =COUNTIF('Test Cases'!B4:B1000,A34) -> 1 | C34: =COUNTIFS('Test Cases'!B4:B1000,A34,'Test Cases'!F4:F1000,"PASS") -> 1 | D34: =COUNTIFS('Test Cases'!B4:B1000,A34,'Test Cases'!F4:F1000,"FAIL") -> 0 | E34: 1 | F34: 0
A35: S1 · Citations | B35: =COUNTIF('Test Cases'!B4:B1000,A35) -> 4 | C35: =COUNTIFS('Test Cases'!B4:B1000,A35,'Test Cases'!F4:F1000,"PASS") -> 4 | D35: =COUNTIFS('Test Cases'!B4:B1000,A35,'Test Cases'!F4:F1000,"FAIL") -> 0 | E35: 4 | F35: 0
A36: S1 · Create conversation | B36: =COUNTIF('Test Cases'!B4:B1000,A36) -> 1 | C36: =COUNTIFS('Test Cases'!B4:B1000,A36,'Test Cases'!F4:F1000,"PASS") -> 1 | D36: =COUNTIFS('Test Cases'!B4:B1000,A36,'Test Cases'!F4:F1000,"FAIL") -> 0 | E36: 1 | F36: 0
A37: S1 · Guardrails | B37: =COUNTIF('Test Cases'!B4:B1000,A37) -> 2 | C37: =COUNTIFS('Test Cases'!B4:B1000,A37,'Test Cases'!F4:F1000,"PASS") -> 2 | D37: =COUNTIFS('Test Cases'!B4:B1000,A37,'Test Cases'!F4:F1000,"FAIL") -> 0 | E37: 2 | F37: 0
A38: S1 · Retrieval quality | B38: =COUNTIF('Test Cases'!B4:B1000,A38) -> 1 | C38: =COUNTIFS('Test Cases'!B4:B1000,A38,'Test Cases'!F4:F1000,"PASS") -> 0 | D38: =COUNTIFS('Test Cases'!B4:B1000,A38,'Test Cases'!F4:F1000,"FAIL") -> 1 | E38: 1 | F38: 1
A39: S1 · Transparency | B39: =COUNTIF('Test Cases'!B4:B1000,A39) -> 2 | C39: =COUNTIFS('Test Cases'!B4:B1000,A39,'Test Cases'!F4:F1000,"PASS") -> 2 | D39: =COUNTIFS('Test Cases'!B4:B1000,A39,'Test Cases'!F4:F1000,"FAIL") -> 0 | E39: 2 | F39: 0
A40: S2 · Rename conversation | B40: =COUNTIF('Test Cases'!B4:B1000,A40) -> 1 | C40: =COUNTIFS('Test Cases'!B4:B1000,A40,'Test Cases'!F4:F1000,"PASS") -> 1 | D40: =COUNTIFS('Test Cases'!B4:B1000,A40,'Test Cases'!F4:F1000,"FAIL") -> 0 | E40: 1 | F40: 0
A41: S2a · Summarise an existing document | B41: =COUNTIF('Test Cases'!B4:B1000,A41) -> 6 | C41: =COUNTIFS('Test Cases'!B4:B1000,A41,'Test Cases'!F4:F1000,"PASS") -> 5 | D41: =COUNTIFS('Test Cases'!B4:B1000,A41,'Test Cases'!F4:F1000,"FAIL") -> 1 | E41: 6 | F41: 1
A42: S2b · Upload then summarise | B42: =COUNTIF('Test Cases'!B4:B1000,A42) -> 4 | C42: =COUNTIFS('Test Cases'!B4:B1000,A42,'Test Cases'!F4:F1000,"PASS") -> 4 | D42: =COUNTIFS('Test Cases'!B4:B1000,A42,'Test Cases'!F4:F1000,"FAIL") -> 0 | E42: 4 | F42: 0
A43: S3 · Delete conversation | B43: =COUNTIF('Test Cases'!B4:B1000,A43) -> 1 | C43: =COUNTIFS('Test Cases'!B4:B1000,A43,'Test Cases'!F4:F1000,"PASS") -> 1 | D43: =COUNTIFS('Test Cases'!B4:B1000,A43,'Test Cases'!F4:F1000,"FAIL") -> 0 | E43: 1 | F43: 0
...

Sheet Test Cases
A1: Test cases — executed functionally through the UI
A2: Expected is what the requirement says. Actual is what was observed, including the server-side record each UI assertion was checked against.
A3: ID | B3: Scenario | C3: Test case | D3: Expected result | E3: Actual result (observed) | F3: Status | G3: Secs | H3: Evidence
A4: TC-01 | B4: Authentication | C4: Sign-in page renders with email and password fields | D4: Login form shows email + password inputs and a Sign in button | E4: email=true password=true signInButton=true | F4: PASS | G4: 1.3 | H4: TC-01-01-login-page.png
A5: TC-02 | B5: Authentication | C5: Wrong password is rejected without revealing which field was wrong | D5: Inline error shown, user stays on /login, no session granted | E5: errorShown=true remainedOnLogin=true url=/login | F5: PASS | G5: 3.7 | H5: TC-02-02-wrong-password-error.png
A6: TC-03 | B6: Authentication | C6: Protected route redirects an unauthenticated visitor to /login | D6: Visiting /library while signed out lands on /login | E6: landed on /login | F6: PASS | G6: 2.6 | H6: TC-03-03-protected-route-redirect.png
A7: TC-04 | B7: Authentication | C7: Valid credentials sign in and land on the chat workspace | D7: Session established, composer and sidebar visible, /api/auth/me returns the user | E7: composer=true sidebar=true me=200 {"email":"dana@example.com","workspaceName":"Dana's workspace"} | F7: PASS | G7: 2.1 | H7: TC-04-01-signed-in-workspace.png
A8: TC-05 | B8: Workspace shell | C8: Sidebar lists conversations grouped by recency | D8: Conversation list renders with at least one group heading and one thread | E8: threads=9 groups=["Today","Yesterday","Previous 7 days","Earlier"] | F8: PASS | G8: 1.6 | H8: TC-05-05-sidebar-conversations.png
A9: TC-06 | B9: Workspace shell | C9: Workspace health card reports indexed and excluded documents | D9: Health card shows counts that match /api/documents statuses | E9: api: 10 documents, 8 ready, 2 not ready; card rendered=true | F9: PASS | G9: 0.1 | H9: TC-06-06-workspace-health.png
A10: TC-07 | B10: Workspace shell | C10: Sidebar search filters conversations and queries the server | D10: Typing a term narrows the list; clearing restores it | E10: before=9 emptyStateShown=true afterClear=9 | F10: PASS | G10: 2.6 | H10: TC-07-07-search-no-match.png TC-07-08-search-cleared.png
A11: TC-08 | B11: Document library | C11: Library lists every document with type, pages and status | D11: A row per document from /api/documents, including non-ready ones with their status | E11: api documents=10 rows=10 namesVisible=9 | F11: PASS | G11: 3.3 | H11: TC-08-09-library-table.png
A12: TC-09 | B12: Document library | C12: A failed document surfaces its failure rather than disappearing | D12: The failed Exhibit Bundle is listed with a failure status, not hidden | E12: failed documents=Exhibit Bundle C (fax).pdf allVisibleInUi=true | F12: PASS | G12: 0.1 | H12: TC-09-10-library-failed-doc.png
A13: TC-10 | B13: Upload & ingestion | C13: Upload dialog states the real limits from the server | D13: Dropzone names PDF/DOCX/TXT, 50 MB, 500 pages, 50 documents — matching /api/config | E13: config=50MB/500p/50docs; dialog states them=true | F13: PASS | G13: 2 | H13: TC-10-11-upload-dialog-limits.png
A14: TC-11 | B14: Upload & ingestion | C14: An unsupported file type is rejected per-file with the reason named | D14: The .pptx is rejected and the reason names the accepted types; the batch is not failed | E14: dialog mentions the rejected file and accepted types=true | F14: PASS | G14: 3.1 | H14: TC-11-12-upload-rejected-pptx.png
A15: TC-12 | B15: Upload & ingestion | C15: Uploading a TXT contract runs the real pipeline through to ready | D15: Document reaches status=ready, classified as contract, with chunks embedded into Qdrant | E15: id=doc_01a13a85078879b598a7989c status=ready type=contract pages=3 | Uploaded:done | Text extracted:done | Layout QA passed:done | Classified:done | Chunked:done | Embedded & indexed:done | F15: PASS | G15: 23.1 | H15: TC-12-13-upload-queued.png TC-12-14-upload-ready.png
... A60: TC-57 | B60: Authentication | C60: Signing out revokes the session server-side | D60: After sign out the app returns to /login and /api/auth/me is 401 | E60: landedOn=/login /api/auth/me=401 | F60: PASS | G60: 6.9 | H60: TC-57-11-signed-out.png
A61: TC-58 | B61: Guardrails | C61: The 60-second generation budget is enforced consistently | D61: A turn that exceeds LL_GENERATION_BUDGET_S=60 is abandoned at ~60s, every time, with the same outcome | E61: Not enforced consistently. Budget is 60s (GET /api/config -> generationBudgetS=60). Observed: (a) 9-field contract summary ran 237.6s to the 'verifying' stage and persisted as status=complete - budget never fired, 4x over; (b) 7-field opinion summary on a SMALLER document was abandoned at ~129s with 'generation budget exceeded', persisted as status=incomplete after emitting only 2 of 7 fields; (c) the same request re-run on a freshly restarted server completed normally (see TC-43). Cause: turns.py:250 wraps an async generator in 'async with asyncio.timeout(...)' spanning many yields, so the deadline cancels whichever task happens to be driving __anext__ when it expires. Outcome is therefore timing-dependent, not budget-dependent. | F61: FAIL | H61: TC-58-01-summary-truncated-by-budget.png logs/DEFECT-03-generation-budget-nondeterministic.log
A62: TC-59 | B62: Stability | C62: The backend survives repeated Summary turns without crashing | D62: Sequential summary requests complete or fail gracefully; the process stays up | E62: FATAL. Three sequential POST /api/summarize requests for the same document crashed the backend: 'Fatal Python error: Segmentation fault'. The faulthandler dump shows two asyncio.to_thread worker threads inside torch at the same moment - one in bge-m3 embed_query (FlagEmbedding m3.encode_single_device, via pipeline.py:115) and one in the bge-reranker cross-encoder (compute_score_single_gpu -> xlm_roberta forward -> sdpa_mask, via rerank.py:107). The model instances are process-level singletons (retrieval/factory.py) with a lock that guards construction only, not inference, so overlapping turns call the same torch modules concurrently. Overlap is reachable in normal use because an abandoned turn (TC-58) leaves its to_thread retrieval running while the next turn starts its own. Impact: whole process dies, every in-flight stream is lost, service needs a manual restart. | F62: FAIL | H62: logs/DEFECT-02-segfault-concurrent-torch.log
A63: TC-60 | B63: Stability | C63: A first Ask turn completes rather than deadlocking the server | D63: The first turn in a fresh process returns an answer | E63: FAILED on the code as committed (commit 9ee3e46), then verified fixed. OrchestratedEngine.__init__ created a non-reentrant threading.Lock(); _ask_workflow() acquired it (orchestrated_engine.py:143) and then called _retriever() (line 148), which acquires the same lock (line 116) -> unconditional self-deadlock on the asyncio event-loop thread. Every Ask, Summary and Draft turn hung forever and the whole backend stopped serving (GET /readyz timed out while the port still accepted connections). Reproduced 3/3 times; stack dump attached. Fixed during this run by changing that one line to threading.RLock(), after which the same turn returned a grounded, cited answer in 58s. All AI test cases in this report were executed against the fixed build. | F63: FAIL | H63: logs/DEFECT-01-deadlock-stacktrace.log logs/DEFECT-01-ask-stream-hangs.sse.txt

Sheet Defects
A1: Defects found
A2: Severity 1 = data loss or service outage. Severity 2 = requirement not met. Severity 3 = quality gap worth a decision.
A3: Ref | B3: Severity | C3: Area | D3: Defect | E3: Root cause (file:line) | F3: Impact | G3: Suggested fix
A4: TC-60 | B4: 1 — blocker | C4: AI orchestration | D4: Every Ask / Summary / Draft turn hangs forever on a fresh process, and the whole backend stops serving requests while still accepting TCP connections. | E4: app/ai/orchestrated_engine.py:75 created a non-reentrant threading.Lock(). _ask_workflow() takes it at line 143 then calls _retriever() at line 148, which takes the same lock at line 116 → self-deadlock on the asyncio event-loop thread. _summary_workflow() (156→161) and _draft_workflow() (167→171) have the same shape. | F4: 100% reproducible. No turn of any kind could complete through the API; GET /readyz timed out. The product's entire value proposition was unreachable. | G4: Use threading.RLock(). Applied during this run and verified — the same turn then returned a grounded, cited answer in 58s. Worth a regression test that drives one turn of each mode through the engine.
A5: TC-59 | B5: 1 — blocker | C5: Retrieval / stability | D5: The backend segfaults and dies when two turns' retrievals overlap. Reproduced with three sequential POST /api/summarize calls. | E5: app/ai/orchestration/retrieval/factory.py caches one bge-m3 embedder and one bge-reranker instance per process; its _lock guards construction only, not inference. summary.py:448 and draft.py:206 dispatch retrieve() via asyncio.to_thread, so two worker threads enter the same torch modules concurrently — crash stack shows m3.encode_single_device (pipeline.py:115) and the cross-encoder's sdpa_mask (rerank.py:107) live at the same instant. | F5: Whole process dies; every in-flight stream is lost; manual restart required. Reachable in ordinary sequential use because an abandoned turn leaves its to_thread retrieval running into the next turn. | G5: Serialise inference with a module-level lock around embed/rerank (or give each a single-worker executor). NFR-5 asks for 10 concurrent users, so a shared GPU/Qdrant-server deployment with a request semaphore is the longer-term answer.
A6: TC-58 | B6: 2 — major | C6: Turn lifecycle | D6: The 60-second generation budget fires at unpredictable times: one summary ran 237.6s and was recorded complete, another was killed at 129s and recorded incomplete after 2 of 7 fields. | E6: app/api/routes/turns.py:250 wraps an async generator in `async with asyncio.timeout(...)` spanning many yields. asyncio.timeout cancels the task driving __anext__ at the moment the deadline passes, so which turn dies — and whether it dies at all — depends on where the event loop happens to be. | F6: Identical requests produce different outcomes. A user can get a silently truncated summary presented as a finished one in the same session where a slower summary succeeded. | G6: Enforce the deadline inside the workflow between stages (check a monotonic deadline before each field / section), or wrap the consumer rather than the generator. Also raise the budget: no real summary fits in 60s on this hardware.
A7: TC-39 | B7: 2 — major | C7: Performance (NFR-3) | D7: NFR-3 requires a 200-page summary in ≤ 3 min. A 3-page, 9-field contract summary took 237.6s (3.96 min). | E7: 9 template fields are retrieved strictly sequentially (summary.py:283 `for template_field in fields[:budget]`), each paying a full bge-m3 embed plus a 25-candidate cross-encoder rerank on CPU. Field retrieval alone was 200s of the 238s. | F7: The stated requirement is missed by a wide margin at 1.5% of the target document size, so the 200-page case is out of reach by orders of magnitude. | G7: Run the field retrievals concurrently (bounded gather) once inference is thread-safe; batch the rerank across fields; move the cross-encoder to GPU or a hosted reranker.
A8: TC-40 | B8: 2 — major | C8: Performance (NFR-1) | D8: NFR-1 requires p95 complete answer ≤ 15s. Across 13 Ask turns: median 29.4s, slowest 142.6s, 0 of 13 within budget. | E8: Cross-encoder reranking dominates every turn (19s–143s of each). Separately, ask.py:168 calls retriever.retrieve() synchronously on the event loop — unlike summary.py and draft.py, which correctly use asyncio.to_thread — so an Ask turn also blocks every other request for its whole retrieval. | F8: Answers are 2–10x over the latency budget, and during an Ask turn the server serves nothing else, which also breaches NFR-5's 10 concurrent users. | G8: Wrap ask.py's retrieve() in asyncio.to_thread for parity with the other two workflows, then reduce rerank cost (GPU, smaller candidate_k, or a hosted reranker).
A9: TC-33 | B9: 3 — quality | C9: Retrieval recall | D9: A natural paraphrase is declined while a near-verbatim question about the same clause is answered. "What is the liability cap and what carve-outs apply to it?" scored best relevance 0.0436 against a 0.25 floor; "What is the cap on each party's total aggregate liability?" cited § 6.1 correctly. | E9: Single-vector bge-m3 similarity plus a 0.25 rerank floor, with no query expansion on a first turn: rewriter.py short-circuits to source="no_history" when there is no prior turn, so a paraphrase gets no help. The document says "Exceptions to the Cap", never "carve-outs". | F9: The refusal is honest and auditable — it names the query it ran and suggests using the document's own wording — but an attorney using ordinary professional shorthand is told the answer is not in a document that plainly contains it. This is a false refusal, counted against the ≥90% correct-refusal target. | G9: Run the rewriter (or a cheap synonym expansion) on first turns too, and consider a lower floor with more aggressive gating downstream. Worth building a labelled paraphrase set to measure recall before tuning.

Sheet Evidence
A1: Screenshot evidence
A2: Captured by Playwright at the moment each assertion was evaluated. Grouped by test case, in test order.
A4: TC-01 — Sign-in page renders with email and password fields [PASS]
A5: Observed: email=true password=true signInButton=true
A6: TC-01-01-login-page.png
A35: TC-02 — Wrong password is rejected without revealing which field was wrong [PASS]
A36: Observed: errorShown=true remainedOnLogin=true url=/login
A37: TC-02-02-wrong-password-error.png
A66: TC-03 — Protected route redirects an unauthenticated visitor to /login [PASS]
A67: Observed: landed on /login
A68: TC-03-03-protected-route-redirect.png
A97: TC-04 — Valid credentials sign in and land on the chat workspace [PASS]
... A2454: log: logs/DEFECT-01-ask-stream-hangs.sse.txt

Sheet Environment
A1: Environment and test data
A2: What was running, and what the tests ran against.
A3: Item | B3: Value | C3: Notes
A4: Platform | B4: macOS (Darwin 24.6.0), Apple silicon, CPU-only inference | C4: No GPU; this is the dominant factor in every latency finding
A5: Backend process | B5: uvicorn app.start:app on 127.0.0.1:8000 | C5: Launched with a SIGUSR1 faulthandler hook to diagnose the hangs
A6: /readyz database | B6: ok
A7: /readyz ingestion worker | B7: running (3/3 workers)
A8: /readyz OCR | B8: ocr/none — pytesseract and rapidocr both absent | C8: Scanned PDFs are quarantined, not indexed. Not exercised; TXT fixtures used
A9: /readyz indexer | B9: indexer/bge-m3+qdrant, vectors available
A10: /readyz generation | B10: orchestrated/m4, grounded=true | C10: Confirms no fixture answers were served
A11: Upload limits (GET /api/config) | B11: 50 MB · 500 pages · 50 documents · .pdf .docx .txt | C11: Asserted against the dialog copy in TC-10
A12: Generation budget | B12: 60s (generationBudgetS) | C12: See TC-58
A13: Seeded fixture corpus | B13: 9 documents incl. a 312-page MSA, 2 opinions, a pleading | C13: Has chunk_meta rows but NO vectors in Qdrant — see note below
A14: Documents uploaded by these tests | B14: Orion-Vertex-Services-Agreement.txt (contract, 3 pp, 27 chunks / 54 points) | C14: Scenario 1 Ask + Scenario 2a Summary + Scenario 3 Draft source
B15: Calder-Ridgeway-Supply-Agreement.txt (contract, uploaded through the UI in TC-12) | C15: Proves the upload path end to end
B16: Thalberg-v-Winslow-Freight.txt (opinion, 2 pp) | C16: Scenario 2b upload-then-summarise
A17: Rejection fixture | B17: unsupported-brief.pptx | C17: TC-11 per-file rejection
A18: Test harness | B18: Playwright 1.64.0 (Chromium, headless, 1600x1000) | C18: 60 cases, 81 screenshots
A19: Spend observed | B19: Ask $0.0075 · Summary $0.066 · Draft $0.065 per turn | C19: NFR-8 caps Ask at $0.05 — Ask is within budget
A21: IMPORTANT — the seeded demo corpus is not retrievable by the real engine. `make seed` writes documents, pages and chunk_meta rows marked `ready`, but no vectors: Qdrant held only two unrelated ad-hoc files at the start of this run. So the README's showcase question — "What happens on a change of control?" against the 312-page MSA, then clicking citation [1] through to page 84 — refuses under LL_AI_ENGINE=auto, correctly but unhelpfully (best relevance 0.00 vs a 0.25 floor). Every grounded result in this report therefore came from documents these tests uploaded. Fix by having `make seed` run the real indexer, or by shipping a pre-built Qdrant collection with the fixtures.
